<?xml version="1.0"?>
<robot name="sul_robot">
  <material name="black">
    <color rgba="0 0 0 1"/>
  </material>
  <material name="white">
    <color rgba="1 1 1 1"/>
  </material>

  <link name="l0">
    <visual>
      <geometry>
        <box size="0.5 0.5 0.5"/>
      </geometry>
      <origin rpy="0 1.57075 0" xyz="0 0 0.3"/>
      <material name="black"/>
    </visual>
    <collision>
      <geometry>
        <cylinder length="0.6" radius="0.2"/>
      </geometry>
    </collision>
    <inertial>
      <mass value="10"/>
      <inertia ixx="1.0" ixy="0.0" ixz="0.0" iyy="1.0" iyz="0.0" izz="1.0"/>
    </inertial>
  </link>

  <link name="l1">
    <visual>
      <geometry>
        <cylinder length="0.6" radius="0.2"/>
      </geometry>
      <origin rpy="0 0 0" xyz="0 0 0.3"/>
      <material name="white"/>
    </visual>
    <collision>
      <geometry>
        <box size="0.6 0.6 0.6"/>
      </geometry>
      <origin rpy="0 1.57075 0" xyz="0 0 0.3"/>
    </collision>
    <inertial>
      <mass value="10"/>
      <inertia ixx="1.0" ixy="0.0" ixz="0.0" iyy="1.0" iyz="0.0" izz="1.0"/>
    </inertial>
  </link>


  <joint name="j1" type="revolute">
    <axis xyz="0 0 -1"/>
    <limit effort="1000.0" lower="-3.14" upper="3.14" velocity="0.5"/>
    <origin rpy="0 0 0" xyz="0 0 0.6"/>
    <parent link="l0"/>
    <child link="l1"/>
  </joint>

  <link name="l2">
    <visual>
      <geometry>
        <box size="0.2 1.2 0.3"/>
      </geometry>
      <origin rpy="0 1.57075 0" xyz="0 0.5 0.1"/>
      <material name="black"/>
    </visual>
    <collision>
      <geometry>
        <cylinder length="0.6" radius="0.2"/>
      </geometry>
    </collision>
    <inertial>
      <mass value="10"/>
      <inertia ixx="1.0" ixy="0.0" ixz="0.0" iyy="1.0" iyz="0.0" izz="1.0"/>
    </inertial>
  </link>  

   <joint name="j2" type="fixed">
    <origin rpy="0 0 0" xyz="0 0 0.6"/>
    <parent link="l1"/>
    <child link="l2"/>
  </joint>



   <link name="l3">
    <visual>
      <geometry>
        <cylinder length="0.8" radius="0.1"/>
      </geometry>
      <origin rpy="0 0 0" xyz="0 0 0"/>
      <material name="white"/>
    </visual>
    <collision>
      <geometry>
        <box size="0 0 0"/>
      </geometry>
      <origin rpy="0 1.57075 0" xyz="0 0 0"/>
    </collision>
    <inertial>
      <mass value="10"/>
      <inertia ixx="1.0" ixy="0.0" ixz="0.0" iyy="1.0" iyz="0.0" izz="1.0"/>
    </inertial>
  </link>

    <joint name="j3" type="prismatic">
    <axis xyz="0 0 1"/>
    <parent link="l2"/>
    <child link="l3"/>
    <limit effort="1000.0" lower="-0.5" upper="0" velocity="0.5"/>
    <origin rpy="0 0 0" xyz="0 1 0.3"/>
  </joint>

   <link name="l4">
    <visual>
      <geometry>
        <cylinder length="0.3" radius="0.2"/>
      </geometry>
      <origin rpy="0 0 0" xyz="0 0 0"/>
      <material name="black"/>
    </visual>
    <collision>
      <geometry>
        <box size="0.4 0.4 0.4"/>
      </geometry>
    </collision>
    <inertial>
      <mass value="10"/>
      <inertia ixx="1.0" ixy="0.0" ixz="0.0" iyy="1.0" iyz="0.0" izz="1.0"/>
    </inertial>
  </link>

    <joint name="j4" type="continuous">
    <axis xyz="0 0 1"/>
    <!--limit effort="1000.0" lower="-3.14" upper="3.14" velocity="0.5"/-->
    <origin rpy="0 0 0" xyz="0 0 -0.5"/>
    <parent link="l3"/>
    <child link="l4"/>
  </joint>


</robot>